const axios = require('axios');

console.log('üîß Teste de Exclus√£o de Lutador...\n');

async function testDeleteFighter() {
    try {
        // 1. Primeiro, vamos criar um lutador de teste
        console.log('1Ô∏è‚É£ Criando lutador de teste...');
        const createResponse = await axios.post('http://localhost:3000/api/fighters', {
            name: 'Test Fighter Delete',
            record: '0-0-0',
            wins: 0,
            losses: 0,
            draws: 0
        });
        
        const fighterId = createResponse.data.id;
        console.log(`   ‚úÖ Lutador criado com ID: ${fighterId}`);
        
        // 2. Agora vamos excluir o lutador
        console.log('\n2Ô∏è‚É£ Excluindo lutador...');
        const deleteResponse = await axios.delete(`http://localhost:3000/api/fighters/${fighterId}`);
        
        console.log('   ‚úÖ Lutador exclu√≠do com sucesso!');
        console.log('   üìã Resposta:', deleteResponse.data);
        
        // 3. Verificar se o lutador foi realmente exclu√≠do
        console.log('\n3Ô∏è‚É£ Verificando se lutador foi exclu√≠do...');
        try {
            await axios.get(`http://localhost:3000/api/fighters/${fighterId}`);
            console.log('   ‚ùå Erro: Lutador ainda existe!');
        } catch (error) {
            if (error.response && error.response.status === 404) {
                console.log('   ‚úÖ Lutador foi exclu√≠do corretamente (404 - n√£o encontrado)');
            } else {
                console.log('   ‚ö†Ô∏è Erro inesperado:', error.message);
            }
        }
        
        console.log('\nüéâ Teste de exclus√£o de lutador conclu√≠do com sucesso!');
        
    } catch (error) {
        console.error('‚ùå Erro no teste:', error.response?.data || error.message);
    }
}

testDeleteFighter(); 